<?xml version="1.0"?>
<robot name="warehouse_bot" xmlns:xacro="http://ros.org/wiki/xacro">

    <xacro:arg name="robot_name" default="robot_1"/>
    <xacro:include filename="$(find warehouse_bot)/urdf/robot_control_gazebo.xacro" />

    <material name="Black">
        <color rgba="0 0 0 1" />
    </material>
    <material name="Grey">
        <color rgba="0.8 0.8 0.8 1" />
    </material>
    <material name="Orange">
        <color rgba="1 0.6 0 1" />
    </material>
    <material name="White">
        <color rgba="1 1 1 1" />
    </material>

    <link name="$(arg robot_name)_base_footprint">
    </link>
    
    <joint name="$(arg robot_name)_base_footprint_joint" type="fixed">
        <parent link="$(arg robot_name)_base_footprint"/>
        <child link="$(arg robot_name)_chassis"/>
        <origin xyz="0 0 0" rpy="0 0 0"/>
    </joint>

    <!-- Chassis -->
    <link name="$(arg robot_name)_chassis">
        <visual>
            <origin xyz="0 0 -0.02" rpy="0 0 0"/>
            <geometry>
                <mesh filename="file://$(find warehouse_bot)/meshes/chassis.stl" scale="0.001 0.001 0.001"/>
            </geometry>
            <material name="Orange"/>
        </visual>
        <collision>
            <origin xyz="0 0 -0.02" rpy="0 0 0"/>
            <geometry>
                <mesh filename="file://$(find warehouse_bot)/meshes/chassis.stl" scale="0.001 0.001 0.001"/>
            </geometry>
        </collision>
        <inertial>
            <origin xyz="0 0 0" rpy="0 0 0" />
            <mass value="70" />
            <inertia ixx="0.126164" ixy="0.0" ixz="0.0" iyy="0.416519" iyz="0.0" izz="0.481014" />
        </inertial>
    </link>

    <!-- Front Steering Hinge Link -->
    <link name="$(arg robot_name)_front_steering_hinge_link">
        <inertial>
            <origin xyz="0 0 0" rpy="0 0 0" />
            <mass value="50" />
            <inertia ixx="4E-06" ixy="0" ixz="0" iyy="4E-06" iyz="0" izz="4E-06" />
        </inertial>
        <visual>
            <origin xyz="0 0 0" rpy="0 0 0" />
            <geometry>
                <box size="0.005 0.005 0.005"/>
            </geometry>
        </visual>
    </link>

    <joint name="$(arg robot_name)_front_steering_hinge_joint" type="revolute">
        <origin xyz="1.1 0 0" rpy="0 0 0" />
        <parent link="$(arg robot_name)_chassis" />
        <child link="$(arg robot_name)_front_steering_hinge_link" />
        <axis xyz="0 0 1" />
        <limit lower="-0.7853" upper="0.7853" effort="10" velocity="100" />
    </joint>

    <!-- Front Wheel Link -->
    <link name="$(arg robot_name)_front_wheel_link">
        <inertial>
            <origin xyz="0.0 0.0 0.0" rpy="0 0 0"/>
            <mass value="2"/>
            <inertia ixx="0.00025" iyy="0.00014" izz="0.00014" ixy="0.0" iyz="0.0" ixz="0.0"/>
        </inertial>
        <visual>
            <origin xyz="0 0 0" rpy="0 0 0"/>
            <geometry>
                <cylinder length="0.05" radius="0.075" />
            </geometry>
            <material name="Black"/>
        </visual>
        <collision>
            <origin xyz="0 0 0" rpy="0 0 0"/>
            <geometry>
                <cylinder length="0.05" radius="0.075" />
            </geometry>
        </collision>
    </link>

    <joint name="$(arg robot_name)_front_wheel_joint" type="continuous">
        <origin xyz="0.0 0.0 0.0" rpy="-1.57 1.57 0" />
        <parent link="$(arg robot_name)_front_steering_hinge_link" />
        <child link="$(arg robot_name)_front_wheel_link" />
        <axis xyz="0 0 1" />
        <limit effort="10" velocity="100" />
    </joint>

    <!-- Rear Left Wheel Link -->
    <link name="$(arg robot_name)_lr_wheel_link">
        <inertial>
            <origin xyz="0.0 0.0 0.0" rpy="0 0 0"/>
            <mass value="2"/>
            <inertia ixx="0.00025" iyy="0.00014" izz="0.00014" ixy="0.0" iyz="0.0" ixz="0.0"/>
        </inertial>
        <visual>
            <geometry>
                <cylinder length="0.04" radius="0.075" />
            </geometry>
            <material name="Black"/>
        </visual>
        <collision>
            <origin xyz="0 0 0" rpy="0 0 0"/>
            <geometry>
                <cylinder length="0.04" radius="0.075" />
            </geometry>
        </collision>
    </link>

    <joint name="$(arg robot_name)_lr_wheel_joint" type="continuous">
        <origin xyz="0 0.2 0" rpy="-1.57 0 0" />
        <parent link="$(arg robot_name)_chassis" />
        <child link="$(arg robot_name)_lr_wheel_link" />
        <axis xyz="0 0 1" />
    </joint>

    <!-- Rear Right Wheel Link -->
    <link name="$(arg robot_name)_rr_wheel_link">
        <inertial>
            <origin xyz="0.0 0.0 0.0" rpy="0 0 0"/>
            <mass value="0.20069792517970372"/>
            <inertia ixx="0.00025" iyy="0.00014" izz="0.00014" ixy="0.0" iyz="0.0" ixz="0.0"/>
        </inertial>
        <visual>
            <origin xyz="0 0 0" rpy="0 0 0"/>
            <geometry>
                <cylinder length="0.04" radius="0.075" />
            </geometry>
            <material name="Black"/>
        </visual>
        <collision>
            <origin xyz="0 0 0" rpy="0 0 0"/>
            <geometry>
                <cylinder length="0.04" radius="0.075" />
            </geometry>
        </collision>
    </link>

    <joint name="$(arg robot_name)_rr_wheel_joint" type="continuous">
        <origin xyz="0 -0.2 0" rpy="-1.57 0 0" />
        <parent link="$(arg robot_name)_chassis" />
        <child link="$(arg robot_name)_rr_wheel_link" />
        <axis xyz="0 0 1" />
    </joint>

    <!-- IMU Link -->
    <link name="$(arg robot_name)_imu_link">
        <inertial>
            <mass value="0.01"/>
            <inertia ixx="1.0" ixy="0" ixz="0" iyy="1.0" iyz="0" izz="1.0"/>
        </inertial>
    </link>

    <joint name="$(arg robot_name)_imu_joint" type="fixed">
        <origin xyz="0.2715 0 0.041" rpy="0 0 0"/>
        <parent link="$(arg robot_name)_chassis"/>
        <child link="$(arg robot_name)_imu_link"/>
    </joint>

    <link name="$(arg robot_name)_line_lidar_1">
        <inertial>
            <origin xyz="0 0 0" rpy="0 0 0"/>
            <mass value="1"/>
            <inertia ixx="0.00068" iyy="0.00068" izz="0.000389" ixy="0.0" iyz="-0.0" ixz="-0.0"/>
        </inertial>
        <visual>
            <origin xyz="-1.1 0.0 -2.26" rpy="0 0 0"/>
            <geometry>
                <mesh filename="file://$(find warehouse_bot)/meshes/16line_lidar_1.stl" scale="0.001 0.001 0.001"/>
            </geometry>
        </visual>
        <collision>
            <origin xyz="-1.1 0.0 -2.26" rpy="0 0 0"/>
            <geometry>
                <mesh filename="file://$(find warehouse_bot)/meshes/16line_lidar_1.stl" scale="0.001 0.001 0.001"/>
            </geometry>
        </collision>
    </link>

    <link name="$(arg robot_name)_laser_frame_under">
        <inertial>
            <origin xyz="0 0 0" rpy="0 0 0"/>
            <mass value="10"/>
            <inertia ixx="0.00068" iyy="0.00068" izz="0.000389" ixy="0.0" iyz="-0.0" ixz="-0.0"/>
        </inertial>
        <visual>
            <origin xyz="-1.475 0 0.005" rpy="3.14 0 0"/>
            <geometry>
                <mesh filename="file://$(find warehouse_bot)/meshes/1line_lidar_1.stl" scale="0.001 0.001 0.001"/>
            </geometry>
        </visual>
        <collision>
            <origin xyz="-1.475 0 0.005" rpy="3.14 0 0"/>
            <geometry>
                <mesh filename="file://$(find warehouse_bot)/meshes/1line_lidar_1.stl" scale="0.001 0.001 0.001"/>
            </geometry>
        </collision>
    </link> 

    <link name="$(arg robot_name)_fork_1">
        <inertial>
            <origin xyz="0 0 0" rpy="0 0 0"/>
            <mass value="10"/>
            <inertia ixx="0.1" ixy="0.0" ixz="0.0" iyy="0.1" iyz="0.0" izz="0.155" />
        </inertial>
        <visual>
            <origin xyz="0.0 0.0 -0.03" rpy="0 0 0"/>
            <geometry>
                <mesh filename="file://$(find warehouse_bot)/meshes/fork_1.stl" scale="0.001 0.001 0.001"/>
            </geometry>
        </visual>
        <collision>
            <origin xyz="0.0 0 -0.03" rpy="0 0 0"/>
            <geometry>
                <mesh filename="file://$(find warehouse_bot)/meshes/fork_1.stl" scale="0.001 0.001 0.001"/>
            </geometry>
        </collision>
    </link>

    <joint name="$(arg robot_name)_fork_joint" type="fixed">
        <origin xyz="0.0 0.0 0.022893" rpy="0 0 0"/>
        <parent link="$(arg robot_name)_chassis"/>
        <child link="$(arg robot_name)_fork_1"/>
    </joint>

    <joint name="$(arg robot_name)_16line_lidar_joint" type="fixed">
        <origin xyz="1.1 0.0 2.24" rpy="0 0 0"/>
        <parent link="$(arg robot_name)_chassis"/>
        <child link="$(arg robot_name)_line_lidar_1"/>
    </joint>

    <joint name="$(arg robot_name)_laser_joint1" type="fixed">
        <origin xyz="1.6 0.0 0.02" rpy="0 0 0"/>
        <parent link="$(arg robot_name)_chassis"/>
        <child link="$(arg robot_name)_laser_frame_under"/>
    </joint> 

</robot>
