<?xml version="1.0"?>
<robot name="robot_1" xmlns:xacro="http://ros.org/wiki/xacro">

    <material name="Black">
      <color rgba="0 0 0 1" />
    </material>
    <material name="Grey">
      <color rgba="0.8 0.8 0.8 1" />
    </material>
    <material name="Orange">
      <color rgba="1 0.6 0 1" />
    </material>
    <material name="White">
      <color rgba="1 1 1 1" />
    </material>

    <link name="base_footprint">
    </link>
    
    <joint name="base_footprint_joint" type="fixed">
      <parent link="base_footprint"/>
      <child link="chassis"/>
      <origin xyz="0 0 0" rpy="0 0 0"/>
    </joint>

    <!-- Chassis -->
    <link name="chassis">
      <visual>
        <origin xyz="0 0 -0.02" rpy="0 0 0"/>
        <geometry>
          <mesh filename="file://$(find warehouse_bot)/meshes/chassis.stl" scale="0.001 0.001 0.001"/>
        </geometry>
        <material name="Orange"/>
      </visual>
      <collision>
        <origin xyz="0 0 -0.02" rpy="0 0 0"/>
        <geometry>
          <mesh filename="file://$(find warehouse_bot)/meshes/chassis.stl" scale="0.001 0.001 0.001"/>
        </geometry>
      </collision>
      <inertial>
        <origin xyz="0 0 0" rpy="0 0 0" />
        <mass value="70" />
        <inertia ixx="0.011642" iyy="0.035651" izz="0.038255" ixy="0.000148" iyz="-9.3e-05" ixz="0.000342"/>
      </inertial>
    </link>



        <!-- Front Steering Hinge Link -->
    <link name="front_steering_hinge_link">
      <inertial>
        <origin xyz="0 0 0" rpy="0 0 0" />
        <mass value="50" />
        <inertia ixx="4E-06" ixy="0" ixz="0" iyy="4E-06" iyz="0" izz="4E-06" />
      </inertial>
      <visual>
        <origin xyz="0 0 0" rpy="0 0 0" />
        <geometry>
          <box size="0.005 0.005 0.005"/>
        </geometry>
      </visual>
    </link>

    <joint name="front_steering_hinge_joint" type="revolute">
      <origin xyz="1.1 0 0" rpy="0 0 0" />
      <parent link="chassis" />
      <child link="front_steering_hinge_link" />
      <axis xyz="0 0 1" />
      <limit lower="-0.7853" upper="0.7853" effort="10" velocity="100" />
    </joint>

    <!-- Front Wheel Link -->
    <link name="front_wheel_link">
      <inertial>
        <origin xyz="0.0 0.0 0.0" rpy="0 0 0"/>
        <mass value="2"/>
        <inertia ixx="0.00025" iyy="0.00014" izz="0.00014" ixy="0.0" iyz="0.0" ixz="0.0"/>
      </inertial>
      <visual>
        <origin xyz="0 0 0" rpy="0 0 0"/>
        <geometry>
          <cylinder length="0.05" radius="0.075" />
        </geometry>
        <material name="black"/>
      </visual>
      <collision>
        <origin xyz="0 0 0" rpy="0 0 0"/>
        <geometry>
          <cylinder length="0.05" radius="0.075" />
        </geometry>
      </collision>
    </link>

    <joint name="front_wheel_joint" type="continuous">
      <origin xyz="0.0 0.0 0.0" rpy="-1.57 1.57 0" />
      <parent link="front_steering_hinge_link" />
      <child link="front_wheel_link" />
      <axis xyz="0 0 1" />
      <limit effort="10" velocity="100" />
    </joint>


  <!-- Rear Left Wheel Link -->
  <link name="lr_wheel_link">
    <inertial>
      <origin xyz="0.0 0.0 0.0" rpy="0 0 0"/>
      <mass value="2"/>
      <inertia ixx="0.00025" iyy="0.00014" izz="0.00014" ixy="0.0" iyz="0.0" ixz="0.0"/>
    </inertial>
    <visual>
        <geometry>
          <cylinder length="0.04" radius="0.075" />
        </geometry>
      <material name="black"/>
    </visual>
    <collision>
      <origin xyz="0 0 0" rpy="0 0 0"/>
        <geometry>
          <cylinder length="0.04" radius="0.075" />
        </geometry>
    </collision>
  </link>

  <joint name="lr_wheel_joint" type="continuous">
    <origin xyz="0 0.2 0" rpy="-1.57 0 0" />
    <parent link="chassis" />
    <child link="lr_wheel_link" />
    <axis xyz="0 0 1" />
  </joint>



  <!-- Rear Right Wheel Link -->
  <link name="rr_wheel_link">
    <inertial>
      <origin xyz="0.0 0.0 0.0" rpy="0 0 0"/>
      <mass value="0.20069792517970372"/>
      <inertia ixx="0.00025" iyy="0.00014" izz="0.00014" ixy="0.0" iyz="0.0" ixz="0.0"/>
    </inertial>
    <visual>
      <origin xyz="0 0 0" rpy="0 0 0"/>
        <geometry>
          <cylinder length="0.04" radius="0.075" />
        </geometry>
      <material name="black"/>
    </visual>
    <collision>
      <origin xyz="0 0 0" rpy="0 0 0"/>
        <geometry>
          <cylinder length="0.04" radius="0.075" />
        </geometry>
    </collision>
  </link>

  <joint name="rr_wheel_joint" type="continuous">
    <origin xyz="0 -0.2 0" rpy="-1.57 0 0" />
    <parent link="chassis" />
    <child link="rr_wheel_link" />
    <axis xyz="0 0 1" />
  </joint>




  <!-- IMU Link -->
  <link name="imu_link">
    <inertial>
      <mass value="0.01"/>
      <inertia ixx="1.0" ixy="0" ixz="0" iyy="1.0" iyz="0" izz="1.0"/>
    </inertial>
  </link>

  <joint name="imu_joint" type="fixed">
    <origin xyz="0.2715 0 0.041" rpy="0 0 0"/>
    <parent link="chassis"/>
    <child link="imu_link"/>
  </joint>


  
  <link name="line_lidar_1">
    <inertial>
      <origin xyz="0 0 0" rpy="0 0 0"/>
      <mass value="1"/>
      <inertia ixx="0.00068" iyy="0.00068" izz="0.000389" ixy="0.0" iyz="-0.0" ixz="-0.0"/>
    </inertial>
    <visual>
      <origin xyz="-1.1 0.0 -2.26" rpy="0 0 0"/>
      <geometry>
        <mesh filename="file://$(find warehouse_bot)/meshes/16line_lidar_1.stl" scale="0.001 0.001 0.001"/>
      </geometry>
    </visual>
    <collision>
      <origin xyz="-1.1 0.0 -2.26" rpy="0 0 0"/>
      <geometry>
        <mesh filename="file://$(find warehouse_bot)/meshes/16line_lidar_1.stl" scale="0.001 0.001 0.001"/>
      </geometry>
    </collision>
  </link>



  <link name="laser_frame_under">
    <inertial>
      <origin xyz="0 0 0" rpy="0 0 0"/>
      <mass value="10"/>
      <inertia ixx="0.00068" iyy="0.00068" izz="0.000389" ixy="0.0" iyz="-0.0" ixz="-0.0"/>
    </inertial>
    <visual>
      <origin xyz="-1.475 0 0.005" rpy="3.14 0 0"/>
      <geometry>
        <mesh filename="file://$(find warehouse_bot)/meshes/1line_lidar_1.stl" scale="0.001 0.001 0.001"/>
      </geometry>
    </visual>
    <collision>
      <origin xyz="-1.475 0 0.005" rpy="3.14 0 0"/>
      <geometry>
        <mesh filename="file://$(find warehouse_bot)/meshes/1line_lidar_1.stl" scale="0.001 0.001 0.001"/>
      </geometry>
    </collision>
  </link> 

  <link name="fork_1">
    <inertial>
      <origin xyz="0 0 0" rpy="0 0 0"/>
      <mass value="10"/>
      <inertia ixx="0.1" ixy="0.0" ixz="0.0" iyy="0.1" iyz="0.0" izz="0.155" />
    </inertial>
    <visual>
      <origin xyz="0.0 0.0 -0.03" rpy="0 0 0"/>
      <geometry>
        <mesh filename="file://$(find warehouse_bot)/meshes/fork_1.stl" scale="0.001 0.001 0.001"/>
      </geometry>
    </visual>
    <collision>
      <origin xyz="0.0 0 -0.03" rpy="0 0 0"/>
      <geometry>
        <mesh filename="file://$(find warehouse_bot)/meshes/fork_1.stl" scale="0.001 0.001 0.001"/>
      </geometry>
    </collision>
  </link>

  <joint name="fork_joint" type="fixed">
    <origin xyz="0.0 0.0 0.022893" rpy="0 0 0"/>
    <parent link="chassis"/>
    <child link="fork_1"/>
  </joint>


  <!-- <xacro:sensor_d435_1 name="camera1" topics_ns="camera1" parent="chassis" publish_pointcloud="true">
    <origin xyz="-0.46 0.19 0.05" rpy="0 0 3.14" />
  </xacro:sensor_d435_1>  

  <xacro:sensor_d435_2 name="camera2" topics_ns="camera2" parent="chassis" publish_pointcloud="true">
    <origin xyz="-0.46 -0.19 0.05" rpy="0 0 3.14" />
  </xacro:sensor_d435_2>  

  <xacro:sensor_d435_3 name="camera3" topics_ns="camera3" parent="chassis" publish_pointcloud="true">
    <origin xyz="1.0 0.0 1.77" rpy="0 2.2 3.14" />
  </xacro:sensor_d435_3>   -->



  <joint name="16line_lidar_joint" type="fixed">
    <origin xyz="1.1 0.0 2.24" rpy="0 0 0"/>
    <parent link="chassis"/>
    <child link="line_lidar_1"/>
  </joint>

  <joint name="laser_joint1" type="fixed">
    <origin xyz="1.6 0.0 0.02" rpy="0 0 0"/>
    <parent link="chassis"/>
    <child link="laser_frame_under"/>
  </joint> 

  <!-- <xacro:mid360 name="livox" parent="chassis" topic="mid360">
    <origin xyz="1.175 0.0 1.67" rpy="3.14 0 0"/>
  </xacro:mid360> -->
  

</robot>